Traceback (most recent call last):
  File "/Users/zhangyiqin/anaconda3/lib/python3.9/site-packages/jupyter_cache/executors/utils.py", line 58, in single_nb_execution
    executenb(
  File "/Users/zhangyiqin/anaconda3/lib/python3.9/site-packages/nbclient/client.py", line 1204, in execute
    return NotebookClient(nb=nb, resources=resources, km=km, **kwargs).execute()
  File "/Users/zhangyiqin/anaconda3/lib/python3.9/site-packages/nbclient/util.py", line 84, in wrapped
    return just_run(coro(*args, **kwargs))
  File "/Users/zhangyiqin/anaconda3/lib/python3.9/site-packages/nbclient/util.py", line 62, in just_run
    return loop.run_until_complete(coro)
  File "/Users/zhangyiqin/anaconda3/lib/python3.9/asyncio/base_events.py", line 647, in run_until_complete
    return future.result()
  File "/Users/zhangyiqin/anaconda3/lib/python3.9/site-packages/nbclient/client.py", line 663, in async_execute
    await self.async_execute_cell(
  File "/Users/zhangyiqin/anaconda3/lib/python3.9/site-packages/nbclient/client.py", line 965, in async_execute_cell
    await self._check_raise_for_error(cell, cell_index, exec_reply)
  File "/Users/zhangyiqin/anaconda3/lib/python3.9/site-packages/nbclient/client.py", line 862, in _check_raise_for_error
    raise CellExecutionError.from_cell_and_msg(cell, exec_reply_content)
nbclient.exceptions.CellExecutionError: An error occurred while executing the following cell:
------------------
import jupytexmagic
%load_ext jupytexmagic
------------------

[0;31m---------------------------------------------------------------------------[0m
[0;31mModuleNotFoundError[0m                       Traceback (most recent call last)
[0;32m/var/folders/df/vqrt_6yx3f962pmw8c8mwxyw0000gn/T/ipykernel_50129/245863205.py[0m in [0;36m<module>[0;34m[0m
[0;32m----> 1[0;31m [0;32mimport[0m [0mjupytexmagic[0m[0;34m[0m[0;34m[0m[0m
[0m[1;32m      2[0m [0mget_ipython[0m[0;34m([0m[0;34m)[0m[0;34m.[0m[0mrun_line_magic[0m[0;34m([0m[0;34m'load_ext'[0m[0;34m,[0m [0;34m'jupytexmagic'[0m[0;34m)[0m[0;34m[0m[0;34m[0m[0m

[0;32m~/anaconda3/lib/python3.9/site-packages/jupytexmagic/__init__.py[0m in [0;36m<module>[0;34m[0m
[1;32m      8[0m [0m__version__[0m [0;34m=[0m [0;34m'0.1.2'[0m[0;34m[0m[0;34m[0m[0m
[1;32m      9[0m [0;34m[0m[0m
[0;32m---> 10[0;31m [0;32mfrom[0m [0;34m.[0m[0mjupytexmagic[0m [0;32mimport[0m [0mload_ipython_extension[0m[0;34m[0m[0;34m[0m[0m
[0m
[0;32m~/anaconda3/lib/python3.9/site-packages/jupytexmagic/jupytexmagic.py[0m in [0;36m<module>[0;34m[0m
[1;32m      3[0m                                 cell_magic, line_cell_magic)
[1;32m      4[0m [0;32mfrom[0m [0mIPython[0m[0;34m.[0m[0mdisplay[0m [0;32mimport[0m [0mSVG[0m[0;34m[0m[0;34m[0m[0m
[0;32m----> 5[0;31m [0;32mfrom[0m [0mPyPDF2[0m [0;32mimport[0m [0mPdfReader[0m[0;34m[0m[0;34m[0m[0m
[0m[1;32m      6[0m [0;32mimport[0m [0msubprocess[0m[0;34m[0m[0;34m[0m[0m
[1;32m      7[0m [0;32mimport[0m [0mtempfile[0m[0;34m[0m[0;34m[0m[0m

[0;31mModuleNotFoundError[0m: No module named 'PyPDF2'
ModuleNotFoundError: No module named 'PyPDF2'

