Traceback (most recent call last):
  File "/home/parallels/.local/lib/python3.10/site-packages/jupyter_cache/executors/utils.py", line 58, in single_nb_execution
    executenb(
  File "/home/parallels/.local/lib/python3.10/site-packages/nbclient/client.py", line 1305, in execute
    return NotebookClient(nb=nb, resources=resources, km=km, **kwargs).execute()
  File "/home/parallels/.local/lib/python3.10/site-packages/jupyter_core/utils/__init__.py", line 173, in wrapped
    return loop.run_until_complete(inner)
  File "/usr/lib/python3.10/asyncio/base_events.py", line 649, in run_until_complete
    return future.result()
  File "/home/parallels/.local/lib/python3.10/site-packages/nbclient/client.py", line 705, in async_execute
    await self.async_execute_cell(
  File "/home/parallels/.local/lib/python3.10/site-packages/nbclient/client.py", line 1058, in async_execute_cell
    await self._check_raise_for_error(cell, cell_index, exec_reply)
  File "/home/parallels/.local/lib/python3.10/site-packages/nbclient/client.py", line 914, in _check_raise_for_error
    raise CellExecutionError.from_cell_and_msg(cell, exec_reply_content)
nbclient.exceptions.CellExecutionError: An error occurred while executing the following cell:
------------------
import jupytexmagic
%load_ext jupytexmagic
------------------


[0;31m---------------------------------------------------------------------------[0m
[0;31mModuleNotFoundError[0m                       Traceback (most recent call last)
Cell [0;32mIn[2], line 1[0m
[0;32m----> 1[0m [38;5;28;01mimport[39;00m [38;5;21;01mjupytexmagic[39;00m
[1;32m      2[0m get_ipython()[38;5;241m.[39mrun_line_magic([38;5;124m'[39m[38;5;124mload_ext[39m[38;5;124m'[39m, [38;5;124m'[39m[38;5;124mjupytexmagic[39m[38;5;124m'[39m)

File [0;32m~/.local/lib/python3.10/site-packages/jupytexmagic/__init__.py:10[0m
[1;32m      7[0m [38;5;66;03m# Rest of your __init__.py code...[39;00m
[1;32m      8[0m __version__ [38;5;241m=[39m [38;5;124m'[39m[38;5;124m0.1.1[39m[38;5;124m'[39m
[0;32m---> 10[0m [38;5;28;01mfrom[39;00m [38;5;21;01m.[39;00m[38;5;21;01mjupytexmagic[39;00m [38;5;28;01mimport[39;00m load_ipython_extension

File [0;32m~/.local/lib/python3.10/site-packages/jupytexmagic/jupytexmagic.py:6[0m
[1;32m      3[0m [38;5;28;01mfrom[39;00m [38;5;21;01mIPython[39;00m[38;5;21;01m.[39;00m[38;5;21;01mcore[39;00m[38;5;21;01m.[39;00m[38;5;21;01mmagic[39;00m [38;5;28;01mimport[39;00m (Magics, magics_class, line_magic,
[1;32m      4[0m                                 cell_magic, line_cell_magic)
[1;32m      5[0m [38;5;28;01mfrom[39;00m [38;5;21;01mIPython[39;00m[38;5;21;01m.[39;00m[38;5;21;01mdisplay[39;00m [38;5;28;01mimport[39;00m SVG
[0;32m----> 6[0m [38;5;28;01mfrom[39;00m [38;5;21;01mPyPDF2[39;00m [38;5;28;01mimport[39;00m PdfReader
[1;32m      7[0m [38;5;28;01mimport[39;00m [38;5;21;01msubprocess[39;00m
[1;32m      8[0m [38;5;28;01mimport[39;00m [38;5;21;01mtempfile[39;00m

[0;31mModuleNotFoundError[0m: No module named 'PyPDF2'

